Workbook

Sheet Cow
C2: Milk Yearly | D2: Milk Monthly | F2: Cow Breed | G2: Feed Type | H2: Economic Difficulty | I2: Sell Price | J2: Grass Harvests
C3: =product(D3,12) -> 49442.4 | D3: =product(Var!B12,D10) -> 4120.2 | F3: Holstein | G3: TMR | H3: Easy | I3: Max Seasonal | J3: 2
B5: Num Cows | C5: Provide Straw | D5: Yield Bonus | F5: Total Mixed Ration Ratio | J5: Should add to 100%
B6: 12 | C6: 1 | D6: 0.425 | F6: Hay | G6: Silage | H6: Straw | I6: Mineral Feed | J6: Total Percent
F7: 0.3744 | G7: 0.3744 | H7: 0.2032 | I7: 0.048 | J7: =sum($F$7:$I$7) -> 1
B8: Production & Consumption
B9: Product | C9: Yearly | D9: Monthly | F9: Mineral feed is optional, but cannot be grown and must be purchased
B10: Milk | C10: =PRODUCT(12,$D10) -> 21600 | D10: =PRODUCT(B6,Rate!$B2,Var!$B$4) -> 1800 | F10: TMR Ingredient | G10: Monthly Usage | H10: Yearly Usage | I10: Monthly Cost | J10: Yearly Cost
B11: Food | C11: =PRODUCT(12,$D11) -> -50400 | D11: =PRODUCT($B$6,Rate!$B3) -> -4200 | F11: Mineral Feed | G11: =Part!$C$5*-1 -> -201.6 | H11: =$G11*12 -> -2419.2 | I11: =$G11*Var!$B$17 -> -192 | J11: =$I$11*12 -> -2304
B12: Slurry | C12: =PRODUCT(12,$D12) -> 36000 | D12: =PRODUCT($B$6,Rate!$B4,Var!$B$2) -> 3000 | F12: Silage | G12: =Part!$C$3*-1 -> -1572.48 | H12: =$G12*12 -> -18869.76
B13: Manure | C13: =PRODUCT(12,$D13) -> 28800 | D13: =PRODUCT(B6,Rate!$B5,Var!$B$2) -> 2400 | F13: Silage usage needs help select appropriately sized bunker silos
B14: Straw | C14: =PRODUCT(12,$D14) -> -13680 | D14: =PRODUCT($B$6,Rate!$B6) -> -1140 | J14: Yearly Beef Sales
F15: TMR Yearly Fieldwork | J15: 3500 | K15: Unit Price
B16: Simple Yearly Fieldwork | F16: Crop | G16: Hectares | H16: Acres | J16: 4 | K16: Sell Count
B17: Crop | C17: Hectares | D17: Acres | F17: Straw Mix | G17: =(Part!$D$4/Var!$B$20)/10000 -> 0.19529519 | H17: =G17/0.4046856 -> 0.48258499 | J17: =$J$15*$J$16 -> 14000 | K17: Total
B18: Straw Bedding | C18: =abs($C$14)/Var!$B$20/10000 -> 0.26086957 | D18: =C18/0.4046856 -> 0.6446228 | F18: Hay Mix | G18: =((Part!$D$2/Yield!F2)/$J$3)/10000 -> 0.15150957 | H18: =G18/0.4046856 -> 0.37438835 | J18: Beef cows reach max sell price of $3,500 at 36 months old.
B19: Grass or Hay | C19: =abs($C$11)/($J$3*Yield!$F2)/10000 -> 0.40467301 | D19: =C19/0.4046856 -> 0.99996889 | F19: Corn Silage | G19: =(Part!$D$3/Yield!F3)/10000 -> 0.18453089 | H19: =G19/0.4046856 -> 0.45598581 | J19: Cow price actually decreases when older than 36 months.
B20: Corn Silage | C20: =abs($C$11)/Yield!$F3/10000 -> 0.49287097 | D20: =C20/0.4046856 -> 1.2179108 | F20: Barley Silage | G20: =(Part!$D$3/Yield!F4)/10000 -> 0.34484211 | H20: =G20/0.4046856 -> 0.85212349 | J20: Sell count is intended to be a rough analog for cows sold per year.
B21: Barley Silage | C21: =abs($C$11)/Yield!$F4/10000 -> 0.92105263 | D21: =C21/0.4046856 -> 2.2759709 | F21: Wheat Silage | G21: =(Part!$D$3/Yield!F5)/10000 -> 0.37196452 | H21: =G21/0.4046856 -> 0.91914444 | J21: Imagine whatever timescale makes sense for your breeding cycle.
B22: Wheat Silage | C22: =abs($C$11)/Yield!$F5/10000 -> 0.99349497 | D22: =C22/0.4046856 -> 2.4549798 | F22: Sorghum Silage | G22: =(Part!$D$3/Yield!F6)/10000 -> 0.40371759 | H22: =G22/0.4046856 -> 0.99760799 | J22: This is oversimplified, but anything else more complicated is currently out of scope.
B23: Sorghum Silage | C23: =abs($C$11)/Yield!$F6/10000 -> 1.0783055 | D23: =C23/0.4046856 -> 2.6645512 | F23: Sunflower Silage | G23: =(Part!$D$3/Yield!F7)/10000 -> 0.42442105 | H23: =G23/0.4046856 -> 1.0487674
B24: Sunflower Silage | C24: =abs($C$11)/Yield!$F7/10000 -> 1.1336032 | D24: =C24/0.4046856 -> 2.8011949 | F24: Oat Silage | G24: =(Part!$D$3/Yield!F8)/10000 -> 0.5807867 | H24: =G24/0.4046856 -> 1.4351553
B25: Oat Silage | C25: =abs($C$11)/Yield!$F8/10000 -> 1.5512465 | D25: =C25/0.4046856 -> 3.8332141 | F25: Canola Silage | G25: =(Part!$D$3/Yield!F9)/10000 -> 0.57077314 | H25: =G25/0.4046856 -> 1.4104113
B26: Canola Silage | C26: =abs($C$11)/Yield!$F9/10000 -> 1.5245009 | D26: =C26/0.4046856 -> 3.7671242 | F26: Soybean Silage | G26: =(Part!$D$3/Yield!F10)/10000 -> 0.73566316 | H26: =G26/0.4046856 -> 1.8178634
B27: Soybean Silage | C27: =abs($C$11)/Yield!$F10/10000 -> 1.9649123 | D27: =C27/0.4046856 -> 4.8554045 | F27: Assumes you will only grow one of the silage crop types to produce the silage for your TMR.
B28: Assumes you will only feed your cows one of these. | F28: The straw acreage needed for TMR is additional to that needed for straw bedding, if any.
B29: Straw bedding is not a feed type and is independent of feed.
B30: Silage needs time to ferment, grass and hay are ready to eat.
F31: NOTES
F32: The grass harvests multiplier is roughly analog to harvesting grass that many times per year.
F33: However, if you harvest grass too often per year you may not get a full yield each at harvest.
F34: Medow regrows monthly except the winter months of Dec, Jan, Feb.
F35: Younger animals eat less. Accounting for this is out of scope.
F36: This does not account for production chains.
F37: Margin of error on feed consumption numbers is typically around 0.01L
F39: LICENSE
F40: This work is contributed into the public domain. You may copy, share or do anything you want with this, without giving the author credit. By using this work, you do so at your own risk, and you agree to release the author from all liability for any damages arising from or relating to your use of this work.

Sheet Sheep
B2: Num Sheep | E2: Num Goats
B3: 12 | E3: 12
B5: Yearly | C5: Monthly | E5: Yearly | F5: Monthly
B6: =$C6*12 -> 30814.306 | C6: =$C$7*Var!$B$33 -> 2567.8588 | D6: Wool Sales | E6: =$F6*12 -> 32892.48 | F6: =$F$7*Var!$B$39 -> 2741.04 | G6: Goat Milk Sales
B7: =$C7*12 -> 8470.5882 | C7: =$B$3*Var!$B$35 -> 705.88235 | D7: Wool (L) | E7: =$F7*12 -> 3600 | F7: =$E$3*25 -> 300 | G7: Goat Milk (L)
B8: =$C8*12 -> 6992.4706 | C8: =$B$3*Var!$B$34 -> 582.70588 | D8: Feed (L) | E8: =$F8*12 -> 7200 | F8: =$E$3*50 -> 600 | G8: Feed (L)
B10: Yearly Fieldwork | E10: Yearly Fieldwork
B11: Hectares | C11: Acres | E11: Hectares | F11: Acres
B12: =$B$8/(4.37*$C$15*Var!$B$36*10000) -> 0.056144129 | C12: =B12/0.4046856 -> 0.13873518 | E12: =$E$8/(4.37*$C$15*Var!$B$36*10000) -> 0.05781043 | F12: =E12/0.4046856 -> 0.1428527
B14: Yield Bonus | C14: Grass Harvests | D14: Difficulty | E14: Sell Price
B15: 0.425 | C15: 2 | D15: Easy | E15: Max Seasonal
B17: NOTES
B18: Sheep and goats only eat grass or hay.
B19: The grass harvests multiplier is roughly analog to harvesting grass that many times per year.
B20: However, if you harvest grass too often per year you may not get a full yield each at harvest.
B21: Medow regrows monthly except the winter months of Dec, Jan, Feb.
B22: Sheep and goats produce their maximum output starting at 18 months old.
B23: This sheet therefor assumes animals are 18 months or older.
B24: Younger animals eat less. Accounting for this is out of scope.
B25: This does not account for production chains.
B26: Margin of error on feed consumption numbers is typically around 0.01L

Sheet Chicken
C2: Num Chx | E2: Yearly | F2: Monthly
C3: 96 | E3: =F3*12 -> 24192 | F3: =$F$4*Var!$B$26*Var!$B$27 -> 2016 | G3: Egg Sales
E4: =$F4*12 -> 5760 | F4: =$C$3*5 -> 480 | G4: Eggs (L)
B5: Difficulty | C5: Easy | E5: =Var!$B$23 -> 5760 | F5: =Var!$B$22 -> 480 | G5: Total Feed (L)
B6: Sell Price | C6: Max Seasonal | E6: =$F6*12 -> 5760 | F6: =product(Var!$B$22,sum(1,product(C17,-1))) -> 480 | G6: Feed Grown (L)
E7: Gross total revenue here does not include feed cost, see below.
E9: Yearly Fieldwork
B10: Yield Bonus | C10: 0.425 | E10: Hectares | F10: Acres
E11: =(($E$6/0.96)/Var!$B$28)/10000 -> 0.42105263 | F11: =$E11/0.4046856 -> 1.0404438 | G11: Barley
E12: =(($E$6/0.89)/Var!$B$28)/10000 -> 0.45416913 | F12: =$E12/0.4046856 -> 1.1222765 | G12: Wheat
E13: =(($E$6/0.82)/Var!$B$28)/10000 -> 0.49293967 | F13: =$E13/0.4046856 -> 1.2180806 | G13: Sorghum
E14: Assumes you choose only one type of crop to grow.
H15: Wheat
E16: Yearly Feed Cost | H16: Oat
B17: Feed Bought | C17: 0 | E17: Cost | F17: Amount | G17: Net
E18: =F18*-1.5 -> 0 | F18: =Var!$B$23*$C$17 -> 0 | G18: =E3+E18 -> 24192
E19: =F19*-1.4 -> 0 | F19: =Var!$B$23*$C$17 -> 0 | G19: =E3+E19 -> 24192
E20: Assumes you choose only one type of feed to buy.
E21: The net income number is the gross revenue from above, minus the feed cost.
E22: The store does not sell sorghum chicken feed, only oat and wheat.
E24: NOTES
E25: Younger animals eat least. Accounting for this is out of scope.
E26: This does not account for production chains.
E27: Margin of error on feed consumption numbers is typically around 0.01L

Sheet Pig
B2: HOW TO USE
B3: For simplicity, you will likely choose one crop per part, in which case you can change its amount to 100% and the others under that type to zero.
B4: For example, you might choose only Canola for a protein part. You can then set Canola to 100% and set Soy and Sunflower to zero.
B7: Change Me | C7: Change Me | E7: Yearly Input & Output | I7: Yearly Pork Sales
B8: Num Pigs | C8: Yield Bonus | E8: Slurry | F8: Straw | G8: Manure | I8: 2500 | J8: Unit Price
B9: 32 | C9: 0.425 | E9: =65*B9*12 -> 24960 | F9: =-20*B9*12 -> -7680 | G9: =35*B9*12 -> 13440 | I9: 16 | J9: Sell Count
I10: =$I$8*$I$9 -> 40000 | J10: Total
C11: Change These | I11: Pigs reach max sell price of $2,500 at 24 months old.
C12: Part Ratios | E12: Yearly Fieldwork | I12: Sell count is intended to be a rough analog for pigs sold per year.
B13: Part | C13: Amount | D13: Ingredient | E13: Hectares | F13: Acres | G13: Liters | I13: Imagine whatever timescale makes sense for your breeding cycle.
B14: Base | C14: 1 | D14: Corn | E14: =($G14/(Var!$B$42*Yield!$B$3))/10000 -> 0.87871854 | F14: =E14/0.4046856 -> 2.171361 | G14: =$B$9*C14*30*12 -> 11520 | I14: This is oversimplified, but anything else more complicated is currently out of scope.
C15: 1 | D15: Sorghum | E15: =($G15/(Var!$B$42*Yield!$B$6))/10000 -> 0.98587933 | F15: =E15/0.4046856 -> 2.4361611 | G15: =$B$9*C15*30*12 -> 11520
B17: Grain | C17: 1 | D17: Wheat | E17: =($G17/(Var!$B$42*Yield!$B$5))/10000 -> 0.45416913 | F17: =E17/0.4046856 -> 1.1222765 | G17: =$B$9*C17*15*12 -> 5760
C18: 1 | D18: Barley | E18: =($G18/(Var!$B$42*Yield!$B$4))/10000 -> 0.42105263 | F18: =E18/0.4046856 -> 1.0404438 | G18: =$B$9*C18*15*12 -> 5760
B20: Protein | C20: 1 | D20: Soy | E20: =($G20/(Var!$B$42*Yield!$B$10))/10000 -> 0.71859649 | F20: =E20/0.4046856 -> 1.7756908 | G20: =$B$9*C20*12*12 -> 4608
C21: 1 | D21: Canola | E21: =($G21/(Var!$B$42*Yield!$B$9))/10000 -> 0.55753176 | F21: =E21/0.4046856 -> 1.3776911 | G21: =$B$9*C21*12*12 -> 4608
C22: 1 | D22: Sunflower | E22: =($G22/(Var!$B$42*Yield!$B$7))/10000 -> 0.62186235 | F22: =E22/0.4046856 -> 1.5366555 | G22: =$B$9*C22*12*12 -> 4608
B24: Root | C24: 1 | D24: Potato | E24: =($G24/(Var!$B$42*Yield!$B11))/10000 -> 0.01957436 | F24: =E24/0.4046856 -> 0.048369301 | G24: =$B$9*C24*3*12 -> 1152
C25: 1 | D25: Sugar Beet | E25: =($G25/(Var!$B$42*Yield!$B12))/10000 -> 0.013986523 | F25: =E25/0.4046856 -> 0.034561456 | G25: =$B$9*C25*3*12 -> 1152
C26: 1 | D26: Red Beet | E26: =($G26/(Var!$B$42*Yield!$B13))/10000 -> 0.013986523 | F26: =E26/0.4046856 -> 0.034561456 | G26: =$B$9*C26*3*12 -> 1152
C27: 1 | D27: Parsnip | E27: =($G27/(Var!$B$42*Yield!$B14))/10000 -> 0.011631958 | F27: =E27/0.4046856 -> 0.028743196 | G27: =$B$9*C27*3*12 -> 1152
C28: 1 | D28: Carrot | E28: =($G28/(Var!$B$42*Yield!$B15))/10000 -> 0.010498975 | F28: =E28/0.4046856 -> 0.025943534 | G28: =$B$9*C28*3*12 -> 1152
B31: NOTES
B32: Straw is optional, but manure is not produced without straw.
B33: Without an appropriate feed, pig health will degrade to zero.
B34: You can achieve 100% pig health on 1) only base feed 2) grain and protein 3) grain and root.
B35: You can ignore the numbers for the feed types you don't intend to provide.
B36: Pigs always eat a fixed amount of each feed type per month, if that feed type is present.
B37: Base feed increases health faster than grain, grain faster than protein, protein faster than root.
B38: For each main part type, you can select one or more specific crops to use for that part type.
B39: For example, for the grain part, you could feed 20% Wheat and 80% Barley, or you could feed only 100% Barley, etc..
B40: Wheat and barley do not count towards the protein part, only towards the grain part, etc..
B41: Margin of error on feed consumption numbers is typically around 0.01L

Sheet Horse
F2: Yearly Input & Output | I2: Yearly Equine Sales
B3: Num Horses | C3: Yield Bonus | D3: Grass Harvests | F3: Straw | G3: Manure | I3: 5000 | J3: Unit Price
B4: 16 | C4: 0.425 | D4: 2 | F4: =-80*B4*12 -> -15360 | G4: =200*B4*12 -> 38400 | I4: 2 | J4: Sell Count
I5: =$I$3*$I$4 -> 10000 | J5: Revenue
E6: Yearly Fieldwork | I6: Horses reach max sell price of $5,000 at 36 months old.
B7: Type | C7: Crop | D7: Ratio | E7: Hectares | F7: Acres | G7: Liters | I7: Sell count is intended to be a rough analog for horses sold per year.
B8: Base | C8: Oat | D8: 1 | E8: =($G8/(Yield!$B$8*Var!$B$53)/10000)*$D8 -> 2.2515235 | F8: =E8/0.4046856 -> 5.5636364 | G8: =$B$4*Var!$B$50*12 -> 18288 | I8: Imagine whatever timescale makes sense for your breeding cycle.
C9: Sorghum | D9: 1 | E9: =($G9/(Yield!$B$6*Var!$B$53)/10000)*$D9 -> 1.5650834 | F9: =E9/0.4046856 -> 3.8674058 | G9: =$B$4*Var!$B$50*12 -> 18288 | I9: This is oversimplified, but anything else more complicated is currently out of scope.
B11: Hay | C11: Hay | D11: 1 | E11: =($G11/(Yield!$B$2*Var!$B$53*$D$4)/10000)*$D11 -> 0.44051548 | F11: =E11/0.4046856 -> 1.0885376 | G11: =$B$4*Var!$B$51*12 -> 54864
B13: Root | C13: Potato | D13: 1 | E13: =($G13/(Yield!$B11*Var!$B$53)/10000)*$D13 -> 0.062189372 | F13: =E13/0.4046856 -> 0.1536733 | G13: =$B$4*Var!$B$52*12 -> 3660
C14: Sugar Beet | D14: 1 | E14: =($G14/(Yield!$B12*Var!$B$53)/10000)*$D14 -> 0.04443635 | F14: =E14/0.4046856 -> 0.10980462 | G14: =$B$4*Var!$B$52*12 -> 3660
C15: Red Beet | D15: 1 | E15: =($G15/(Yield!$B13*Var!$B$53)/10000)*$D15 -> 0.04443635 | F15: =E15/0.4046856 -> 0.10980462 | G15: =$B$4*Var!$B$52*12 -> 3660
C16: Parsnip | D16: 1 | E16: =($G16/(Yield!$B14*Var!$B$53)/10000)*$D16 -> 0.036955699 | F16: =E16/0.4046856 -> 0.09131953 | G16: =$B$4*Var!$B$52*12 -> 3660
C17: Carrot | D17: 1 | E17: =($G17/(Yield!$B15*Var!$B$53)/10000)*$D17 -> 0.033356118 | F17: =E17/0.4046856 -> 0.08242477 | G17: =$B$4*Var!$B$52*12 -> 3660
C18: Assumes you will feed only one of these
C19: Change the ratios for other hypothetical scenarios.
B20: NOTES
B21: The grass harvests multiplier is roughly analog to harvesting grass that many times per year.
B22: However, if you harvest grass too often per year you may not get a full yield each at harvest.
B23: Straw is optional, but manure is not produced without straw. Horses do not produce slurry.
B24: Horse feed mechanics are not intuitive.
B25: The game UI lists percentages that have nothing to do with how much horses eat.
B26: Though for pigs they are representative of how much pigs eat.
B27: Root crops are not mentioned in the game help nor academy, yet they are valid horse feed.
B28: You can feed any single crop type only and still achieve 100% horse health.
B29: The different horse feed types appear to be purely player preference.
B30: Horses always eat a fixed amount of each given feed type.
B31: For example, feeding root crops in addition to base feed does not change the amount of base feed consumed.
... B33: Margin of error on feed consumption numbers is typically around 0.01L

Sheet Yield
A1: Name | B1: Yield | C1: Chaff Mulitplier | D1: Chaff Yield | E1: Yield With Bonus | F1: Chaff Yield With Bonus
A2: Grass | B2: 4.37 | C2: 1 | D2: =product(B2,C2) -> 4.37 | E2: =product(B2,Var!$B$1) -> 6.22725 | F2: =product(D2,Var!$B$1) -> 6.22725
A3: Corn | B3: 0.92 | C3: 7.8 | D3: =product(B3,C3) -> 7.176 | E3: =product(B3,Var!$B$1) -> 1.311 | F3: =product(D3,Var!$B$1) -> 10.2258
A4: Barley | B4: 0.96 | C4: 4 | D4: =product(B4,C4) -> 3.84 | E4: =product(B4,Var!$B$1) -> 1.368 | F4: =product(D4,Var!$B$1) -> 5.472
A5: Wheat | B5: 0.89 | C5: 4 | D5: =product(B5,C5) -> 3.56 | E5: =product(B5,Var!$B$1) -> 1.26825 | F5: =product(D5,Var!$B$1) -> 5.073
A6: Sorghum | B6: 0.82 | C6: 4 | D6: =product(B6,C6) -> 3.28 | E6: =product(B6,Var!$B$1) -> 1.1685 | F6: =product(D6,Var!$B$1) -> 4.674
A7: Sunflower | B7: 0.52 | C7: 6 | D7: =product(B7,C7) -> 3.12 | E7: =product(B7,Var!$B$1) -> 0.741 | F7: =product(D7,Var!$B$1) -> 4.446
A8: Oat | B8: 0.57 | C8: 4 | D8: =product(B8,C8) -> 2.28 | E8: =product(B8,Var!$B$1) -> 0.81225 | F8: =product(D8,Var!$B$1) -> 3.249
A9: Canola | B9: 0.58 | C9: 4 | D9: =product(B9,C9) -> 2.32 | E9: =product(B9,Var!$B$1) -> 0.8265 | F9: =product(D9,Var!$B$1) -> 3.306
A10: Soybean | B10: 0.45 | C10: 4 | D10: =product(B10,C10) -> 1.8 | E10: =product(B10,Var!$B$1) -> 0.64125 | F10: =product(D10,Var!$B$1) -> 2.565
A11: Potato | B11: 4.13 | C11: 1 | D11: =product(B11,C11) -> 4.13 | E11: =product(B11,Var!$B$1) -> 5.88525 | F11: =product(D11,Var!$B$1) -> 5.88525
A12: Sugar Beet | B12: 5.78
A13: Red Beet | B13: 5.78
A14: Parsnip | B14: 6.95
A15: Carrot | B15: 7.7

Sheet Var
A1: yield bonus scalar | B1: =sum(1,Cow!$D$6) -> 1.425
A2: base prod rate | B2: =if(Cow!G3="TMR",1,if(Cow!G3="Hay",0.8,if(Cow!G3="Silage",0.8,if(Cow!G3="Grass",0.4,0.4)))) -> 1
A3: straw bonus | B3: =if(Cow!C6=1,0.11111111,0) -> 0.11111111
A4: prod with straw | B4: =sum(B2,B3) -> 1.1111111
A6: buffalo milk scalar | B6: =if(Cow!$F$3="Water Buffalo",5,1) -> 1
A7: base milk price | B7: =product(0.7,Var!$B$6) -> 0.7
A8: cow difficulty scalar | B8: =if(Cow!H3="Hard",1,if(Cow!H3="Normal",1.8,3)) -> 3
A9: difficulty scaled price | B9: =product($B$7,$B$8) -> 2.1
A11: opt seasonal price scalar | B11: =if(Cow!$I$3="Average",1.003333,1.09) -> 1.09
A12: unit milk price | B12: =product(Var!$B$9,Var!$B$11) -> 2.289
A14: is dairy? | B14: =if(Var!$B$15="Dairy",1,0) -> 1
A15: cattle type | B15: =if(Cow!$F$3="Angus","Beef",if(Cow!$F$3="Limousin","Beef","Dairy")) -> Dairy
A17: mineral feed price | B17: =1000/1050 -> 0.95238095
A19: feed type is tmr | B19: =if(Cow!G3="TMR",1,0) -> 1
A20: straw bonus yield | B20: =product(3.68,Var!$B$1) -> 5.244
A22: chx monthly feed total | B22: =Chicken!$C$3*5 -> 480
A23: chx yearly feed total | B23: =B22*12 -> 5760
A24: egg price scalar | B24: =if(Chicken!$C$6="Baseline",1,1.25) -> 1.25
A25: egg base price | B25: 1.12
A26: egg sell price | B26: =$B$25*$B$24 -> 1.4
A27: chicken difficulty scalar | B27: =if(Chicken!$C$5="Hard",1,if(Chicken!$C$5="Normal",1.8,3)) -> 3
A28: chicken yield scalar | B28: =sum(1,Chicken!$C$10) -> 1.425
A30: base wool price | B30: 0.94
A31: wool price scalar | B31: =if(Sheep!$E$15="Baseline",1,1.29) -> 1.29
A32: sheep difficulty scalar | B32: =if(Sheep!$D$15="Hard",1,if(Sheep!$D$15="Normal",1.8,3)) -> 3
A33: real wool sell price | B33: =$B$30*$B$31*$B$32 -> 3.6378
A34: monthly feed per sheep | B34: 48.558824
A35: monthly wool per sheep | B35: 58.823529
A36: sheep yield bonus scalar | B36: =sum(1,Sheep!$B$15) -> 1.425
A37: base goat milk price | B37: 2.82
A38: goat milk price scalar | B38: =if(Sheep!$E$15="Baseline",1,1.08) -> 1.08
A39: real goat milk price | B39: =$B$37*$B$38*$B$32 -> 9.1368
A41: pig feed per month | B41: 61.818182
A42: pig yield bonus scalar | B42: =sum(1,Pig!$C$9) -> 1.425
A43: pig base liters | B43: =Var!$B$48*0.5 -> 11869.091
A44: pig grain liters | B44: =Var!$B$48*0.25 -> 5934.5455
A45: pig protein liters | B45: =Var!$B$48*0.2 -> 4747.6364
A46: pig root liters | B46: =Var!$B$48*0.05 -> 1186.9091
A47: pig monthly feed total | B47: =Pig!$B$9*Var!$B$41 -> 1978.1818
A48: pig yearly feed total | B48: =Var!$B$47*12 -> 23738.182
...

Sheet Part
A1: Ingredient Name | B1: Need Liters/Month | C1: TMR Need/mo Toggle | D1: Need Liters/Year
A2: Hay | B2: =Cow!$D$11*-1*Cow!$F$7 -> 1572.48 | C2: =$B2*Var!$B$19 -> 1572.48 | D2: =product($C2,12) -> 18869.76
A3: Silage | B3: =Cow!$D$11*-1*Cow!$G$7 -> 1572.48 | C3: =$B3*Var!$B$19 -> 1572.48 | D3: =product($C3,12) -> 18869.76
A4: Straw | B4: =Cow!$D$11*-1*Cow!$H$7 -> 853.44 | C4: =$B4*Var!$B$19 -> 853.44 | D4: =product($C4,12) -> 10241.28
A5: Mineral Feed | B5: =Cow!$D$11*-1*Cow!$I$7 -> 201.6 | C5: =$B5*Var!$B$19 -> 201.6 | D5: =product($C5,12) -> 2419.2

Sheet Discount
A1: Month Num | B1: Month Name | C1: Milk Price Scalar
A2: 1 | B2: MAR | C2: 1.06
A3: 2 | B3: APR | C3: 1.01
A4: 3 | B4: MAY | C4: 0.96
A5: 4 | B5: JUN | C5: 0.9
A6: 5 | B6: JUL | C6: 0.95
A7: 6 | B7: AGU | C7: 0.95
A8: 7 | B8: SEP | C8: 1.03
A9: 8 | B9: OCT | C9: 1.09
A10: 9 | B10: NOV | C10: 0.98
A11: 10 | B11: DEC | C11: 0.96
A12: 11 | B12: JAN | C12: 1.08
A13: 12 | B13: FEB | C13: 1.07
C14: =AVERAGE(C2:C13) -> 1.0033333 | D14: average
C15: =MAX(C2:C13) -> 1.09 | D15: max

Sheet Rate
B1: Amount
A2: Milk | B2: =if(Var!$B$14,if(Cow!$F$3="Water Buffalo",27,135),0) -> 135
A3: Food | B3: =if(Var!$B$14,-350,-550) -> -350
A4: Slurry | B4: 250
A5: Manure | B5: =product($B$7,Cow!$C$6) -> 200
A6: Straw | B6: =product($B$8,Cow!$C$6) -> -95
A7: Manure Rate | B7: =if(Var!$B$14,200,300) -> 200
A8: Straw Rate | B8: =if(Var!$B$14=1,-95,-135) -> -95
